<?xml version="1.0"?>
<!--
   simple_humanoid URDF model

   FIXME: fill missing data: sole, gripper and sensors
  -->
<robot xmlns:xacro="http://ros.org/wiki/xacro" name="test_two_link">

  <link name="base_link"/>
  <joint name="JOINT1" type="revolute"> 
    <axis xyz="0 0 1"/>
    <parent link="base_link"/>
    <child link="CHILD1"/>
    <origin xyz="1 0 0"/>
    <limit effort="12" lower="0" upper="3.14" velocity="10"/>
  </joint>


  <link name="CHILD1">
    <inertial>
      <origin xyz="0.5 0 0" rpy="0 0 0"/>
      <mass value="10"/>
      <inertia ixx="1" ixy="0" ixz="0" iyy="1" iyz="0" izz="1" />
    </inertial>
  </link>
    <joint name="JOINT2" type="revolute">
    <axis xyz="0 0 1"/>
    <parent link="CHILD1"/>
    <child link="CHILD2"/>
    <origin xyz="1 0 0"/>
    <limit effort="12" lower="0" upper="3.14" velocity="10"/>
  </joint>
  <link name="CHILD2">
    <inertial>
      <origin xyz="0.5 0 0" rpy="0 0 0"/>
      <mass value="20"/>
      <inertia ixx="1" ixy="0" ixz="0" iyy="1" iyz="0" izz="1" />
    </inertial>
  </link>
<!--
  <link name="CHILD3">
    <inertial>
      <origin xyz="0.5 0 0" rpy="0 0 0"/>
      <mass value="20"/>
      <inertia ixx="1" ixy="0" ixz="0" iyy="1" iyz="0" izz="1" />
    </inertial>
  </link>
  <link name="CHILD4">
    <inertial>
      <origin xyz="0.5 0 0" rpy="0 0 0"/>
      <mass value="20"/>
      <inertia ixx="1" ixy="0" ixz="0" iyy="1" iyz="0" izz="1" />
    </inertial>
  </link>
  <link name="CHILD5">
    <inertial>
      <origin xyz="0.5 0 0" rpy="0 0 0"/>
      <mass value="20"/>
      <inertia ixx="1" ixy="0" ixz="0" iyy="1" iyz="0" izz="1" />
    </inertial>
  </link>
  <joint name="JOINT3" type="revolute">
    <axis xyz="0 0 1"/>
    <parent link="CHILD2"/>
    <child link="CHILD3"/>
    <origin xyz="1 0 0"/>
    <limit effort="100" lower="0" upper="3.14" velocity="10"/>
  </joint>
  <joint name="JOINT4" type="revolute">
    <axis xyz="0 0 1"/>
    <parent link="CHILD3"/>
    <child link="CHILD4"/>
    <origin xyz="1 0 0"/>
    <limit effort="100" lower="0" upper="3.14" velocity="10"/>
  </joint>
  <joint name="JOINT5" type="revolute">
    <axis xyz="0 0 1"/>
    <parent link="CHILD4"/>
    <child link="CHILD5"/>
    <origin xyz="1 0 0"/>
    <limit effort="100" lower="0" upper="3.14" velocity="10"/>
  </joint>
-->
</robot>
